Workbook

Sheet Model
A1: UBER model (history) as of 2026-08-06
A2: line | B2: unit | C2: 2023Q1 | D2: 2023Q2 | E2: 2023Q3 | F2: 2023Q4 | G2: FY2023 | H2: 2024Q1 | I2: 2024Q2 | J2: 2024Q3 | K2: 2024Q4 | L2: FY2024 | M2: 2025Q1 | N2: 2025Q2 | O2: 2025Q3 | P2: 2025Q4 | Q2: FY2025 | R2: 2026Q1 | S2: 2026Q2 | T2: 2026Q3 | U2: 2026Q4 | V2: FY2026 | W2: 2027Q1 | X2: 2027Q2 | Y2: 2027Q3 | Z2: 2027Q4 | AA2: FY2027
A3: Operating build
A4: trips | B4: count millions | C4: 2124 | D4: 2282 | E4: 2441 | F4: 2601 | G4: =SUM(C4:F4) | H4: 2572 | I4: 2765 | J4: 2868 | K4: 3068 | L4: =SUM(H4:K4) | M4: 3036 | N4: 3268 | O4: 3512 | P4: 3751 | Q4: =SUM(M4:P4) | R4: 3643 | S4: 3867 | T4: =IFERROR(IF(COUNT(O4)=1,O4,J4*(1+T30)),J4*(1+T30))*(1+T30) | U4: =IFERROR(IF(COUNT(P4)=1,P4,K4*(1+U30)),K4*(1+U30))*(1+U30) | V4: =SUM(R4:U4) | W4: =IFERROR(IF(COUNT(R4)=1,R4,M4*(1+W30)),M4*(1+W30))*(1+W30) | X4: =IFERROR(IF(COUNT(S4)=1,S4,N4*(1+X30)),N4*(1+X30))*(1+X30) | Y4: =IFERROR(IF(COUNT(T4)=1,T4,O4*(1+Y30)),O4*(1+Y30))*(1+Y30) | Z4: =IFERROR(IF(COUNT(U4)=1,U4,P4*(1+Z30)),P4*(1+Z30))*(1+Z30) | AA4: =SUM(W4:Z4)
A5: monthly active platform consumers | B5: count millions | C5: 130 | D5: 137 | E5: 142 | F5: 150 | H5: 149 | I5: 156 | J5: 161 | K5: 171 | M5: 170 | N5: 180 | O5: 189 | P5: 202 | R5: 199 | S5: 208
A6: gross bookings mobility | B6: USD millions | C6: 14981 | D6: 16728 | E6: 17903 | F6: 19285 | G6: =SUM(C6:F6) | H6: 18670 | I6: 20554 | J6: 21002 | K6: 22798 | L6: =SUM(H6:K6) | M6: 21182 | N6: 23762 | O6: 25111 | P6: 27442 | Q6: =SUM(M6:P6) | R6: 26394 | S6: 28988 | T6: =O6*(1+T25) | U6: =P6*(1+U25) | V6: =SUM(R6:U6) | W6: =R6*(1+W25) | X6: =S6*(1+X25) | Y6: =T6*(1+Y25) | Z6: =U6*(1+Z25) | AA6: =SUM(W6:Z6)
A7: gross bookings delivery | B7: USD millions | C7: 15026 | D7: 15595 | E7: 16094 | F7: 17011 | G7: =SUM(C7:F7) | H7: 17699 | I7: 18126 | J7: 18663 | K7: 20126 | L7: =SUM(H7:K7) | M7: 20377 | N7: 21734 | O7: 23322 | P7: 25431 | Q7: =SUM(M7:P7) | R7: 25992 | S7: 27463 | T7: =O7*(1+T26) | U7: =P7*(1+U26) | V7: =SUM(R7:U7) | W7: =R7*(1+W26) | X7: =S7*(1+X26) | Y7: =T7*(1+Y26) | Z7: =U7*(1+Z26) | AA7: =SUM(W7:Z7)
A8: gross bookings freight | B8: USD millions | C8: 1401 | D8: 1278 | E8: 1284 | F8: 1279 | G8: =SUM(C8:F8) | H8: 1282 | I8: 1272 | J8: 1308 | K8: 1273 | L8: =SUM(H8:K8) | M8: 1259 | N8: 1260 | O8: 1307 | P8: 1267 | Q8: =SUM(M8:P8) | R8: 1334 | S8: 1571 | T8: =O8*(1+T27) | U8: =P8*(1+U27) | V8: =SUM(R8:U8) | W8: =R8*(1+W27) | X8: =S8*(1+X27) | Y8: =T8*(1+Y27) | Z8: =U8*(1+Z27) | AA8: =SUM(W8:Z8)
A9: gross bookings | B9: USD millions | C9: 31408 | D9: 33601 | E9: 35281 | F9: 37575 | G9: =SUM(C9:F9) | H9: 37651 | I9: 39952 | J9: 40973 | K9: 44197 | L9: =SUM(H9:K9) | M9: 42818 | N9: 46756 | O9: 49740 | P9: 54140 | Q9: =SUM(M9:P9) | R9: 53720 | S9: 58022 | T9: =(T6+T7)+T8 | U9: =(U6+U7)+U8 | V9: =SUM(R9:U9) | W9: =(W6+W7)+W8 | X9: =(X6+X7)+X8 | Y9: =(Y6+Y7)+Y8 | Z9: =(Z6+Z7)+Z8 | AA9: =SUM(W9:Z9)
A10: gross bookings per trip (Mobility and Delivery) | B10: USD | C10: =(C6+C7)/C4 | D10: =(D6+D7)/D4 | E10: =(E6+E7)/E4 | F10: =(F6+F7)/F4 | G10: =(G6+G7)/G4 | H10: =(H6+H7)/H4 | I10: =(I6+I7)/I4 | J10: =(J6+J7)/J4 | ... AA10: =(AA6+AA7)/AA4
A11: revenue mobility | B11: USD millions | C11: 4330 | D11: 4894 | E11: 5071 | F11: 5537 | G11: =SUM(C11:F11) | H11: 5633 | I11: 6134 | J11: 6409 | K11: 6911 | L11: =SUM(H11:K11) | M11: 6496 | N11: 7288 | O11: 7682 | P11: 8204 | Q11: =SUM(M11:P11) | R11: 6798 | S11: 7363 | T11: =T6*T14 | U11: =U6*U14 | V11: =SUM(R11:U11) | W11: =W6*W14 | X11: =X6*X14 | Y11: =Y6*Y14 | Z11: =Z6*Z14 | AA11: =SUM(W11:Z11)
A12: revenue delivery | B12: USD millions | C12: 3093 | D12: 3057 | E12: 2935 | F12: 3119 | G12: =SUM(C12:F12) | H12: 3214 | I12: 3293 | J12: 3470 | K12: 3773 | L12: =SUM(H12:K12) | M12: 3777 | N12: 4102 | O12: 4477 | P12: 4892 | Q12: =SUM(M12:P12) | R12: 5068 | S12: 5245 | T12: =T7*T15 | U12: =U7*U15 | V12: =SUM(R12:U12) | W12: =W7*W15 | X12: =X7*X15 | Y12: =Y7*Y15 | Z12: =Z7*Z15 | AA12: =SUM(W12:Z12)
A13: revenue freight | B13: USD millions | C13: 1400 | D13: 1279 | E13: 1286 | F13: 1280 | G13: =SUM(C13:F13) | H13: 1284 | I13: 1273 | J13: 1309 | K13: 1275 | L13: =SUM(H13:K13) | M13: 1260 | N13: 1261 | O13: 1308 | P13: 1270 | Q13: =SUM(M13:P13) | R13: 1337 | S13: 1583 | T13: =T8*T16 | U13: =U8*U16 | V13: =SUM(R13:U13) | W13: =W8*W16 | X13: =X8*X16 | Y13: =Y8*Y16 | Z13: =Z8*Z16 | AA13: =SUM(W13:Z13)
A14: take rate mobility | B14: fraction | C14: =C11/C6 | D14: =D11/D6 | E14: =E11/E6 | F14: =F11/F6 | G14: =G11/G6 | H14: =H11/H6 | I14: =I11/I6 | J14: =J11/J6 | ... S14: =S11/S6 | T14: =MIN(MAX(IFERROR(IF(COUNT(O14)=1,O14,J14),J14)+T31,Assumptions!$B$23),Assumptions!$B$22) | U14: =MIN(MAX(IFERROR(IF(COUNT(P14)=1,P14,K14),K14)+U31,Assumptions!$B$23),Assumptions!$B$22) | V14: =V11/V6 | W14: =MIN(MAX(IFERROR(IF(COUNT(R14)=1,R14,M14),M14)+W31,Assumptions!$B$23),Assumptions!$B$22) | X14: =MIN(MAX(IFERROR(IF(COUNT(S14)=1,S14,N14),N14)+X31,Assumptions!$B$23),Assumptions!$B$22) | Y14: =MIN(MAX(IFERROR(IF(COUNT(T14)=1,T14,O14),O14)+Y31,Assumptions!$B$23),Assumptions!$B$22) | Z14: =MIN(MAX(IFERROR(IF(COUNT(U14)=1,U14,P14),P14)+Z31,Assumptions!$B$23),Assumptions!$B$22) | AA14: =AA11/AA6
A15: take rate delivery | B15: fraction | C15: =C12/C7 | D15: =D12/D7 | E15: =E12/E7 | F15: =F12/F7 | G15: =G12/G7 | H15: =H12/H7 | I15: =I12/I7 | J15: =J12/J7 | ... S15: =S12/S7 | T15: =MIN(MAX(IFERROR(IF(COUNT(O15)=1,O15,J15),J15)+T32,Assumptions!$B$17),Assumptions!$B$16) | U15: =MIN(MAX(IFERROR(IF(COUNT(P15)=1,P15,K15),K15)+U32,Assumptions!$B$17),Assumptions!$B$16) | V15: =V12/V7 | W15: =MIN(MAX(IFERROR(IF(COUNT(R15)=1,R15,M15),M15)+W32,Assumptions!$B$17),Assumptions!$B$16) | X15: =MIN(MAX(IFERROR(IF(COUNT(S15)=1,S15,N15),N15)+X32,Assumptions!$B$17),Assumptions!$B$16) | Y15: =MIN(MAX(IFERROR(IF(COUNT(T15)=1,T15,O15),O15)+Y32,Assumptions!$B$17),Assumptions!$B$16) | Z15: =MIN(MAX(IFERROR(IF(COUNT(U15)=1,U15,P15),P15)+Z32,Assumptions!$B$17),Assumptions!$B$16) | AA15: =AA12/AA7
A16: take rate freight | B16: fraction | C16: =C13/C8 | D16: =D13/D8 | E16: =E13/E8 | F16: =F13/F8 | G16: =G13/G8 | H16: =H13/H8 | I16: =I13/I8 | J16: =J13/J8 | ... S16: =S13/S8 | T16: =MIN(MAX(IFERROR(IF(COUNT(O16)=1,O16,J16),J16)+T33,Assumptions!$B$20),Assumptions!$B$19) | U16: =MIN(MAX(IFERROR(IF(COUNT(P16)=1,P16,K16),K16)+U33,Assumptions!$B$20),Assumptions!$B$19) | V16: =V13/V8 | W16: =MIN(MAX(IFERROR(IF(COUNT(R16)=1,R16,M16),M16)+W33,Assumptions!$B$20),Assumptions!$B$19) | X16: =MIN(MAX(IFERROR(IF(COUNT(S16)=1,S16,N16),N16)+X33,Assumptions!$B$20),Assumptions!$B$19) | Y16: =MIN(MAX(IFERROR(IF(COUNT(T16)=1,T16,O16),O16)+Y33,Assumptions!$B$20),Assumptions!$B$19) | Z16: =MIN(MAX(IFERROR(IF(COUNT(U16)=1,U16,P16),P16)+Z33,Assumptions!$B$20),Assumptions!$B$19) | AA16: =AA13/AA8
A17: take rate (total) | B17: fraction | C17: =C47/C9 | D17: =D47/D9 | E17: =E47/E9 | F17: =F47/F9 | G17: =G47/G9 | H17: =H47/H9 | I17: =I47/I9 | J17: =J47/J9 | ... AA17: =AA47/AA9
A18: adj ebitda mobility | B18: USD millions | C18: 1060 | D18: 1170 | E18: 1287 | F18: 1446 | G18: =SUM(C18:F18) | H18: 1479 | I18: 1567 | J18: 1682 | K18: 1769 | L18: =SUM(H18:K18) | M18: 1753 | N18: 1905 | O18: 2038 | P18: 2203 | Q18: =SUM(M18:P18)
A19: adj ebitda delivery | B19: USD millions | C19: 288 | D19: 329 | E19: 413 | F19: 476 | G19: =SUM(C19:F19) | H19: 528 | I19: 588 | J19: 628 | K19: 727 | L19: =SUM(H19:K19) | M19: 763 | N19: 873 | O19: 921 | P19: 1015 | Q19: =SUM(M19:P19)
A20: adj ebitda freight | B20: USD millions | C20: -23 | D20: -14 | E20: -13 | F20: -14 | G20: =SUM(C20:F20) | H20: -21 | I20: -12 | J20: -19 | K20: -22 | L20: =SUM(H20:K20) | M20: -7 | N20: -6 | O20: -20 | P20: 0 | Q20: =SUM(M20:P20)
A21: corporate G&A and platform R&D | B21: USD millions | C21: -564 | D21: -569 | E21: -595 | F21: -625 | G21: =SUM(C21:F21) | H21: -604 | I21: -573 | J21: -601 | K21: -632 | L21: =SUM(H21:K21) | M21: -641 | N21: -653 | O21: -683 | P21: -731 | Q21: =SUM(M21:P21)
A22: Mobility adj. EBITDA margin on gross bookings | B22: fraction | C22: =C18/C6 | D22: =D18/D6 | E22: =E18/E6 | F22: =F18/F6 | G22: =G18/G6 | H22: =H18/H6 | I22: =I18/I6 | J22: =J18/J6 | ... Q22: =Q18/Q6
A23: Delivery adj. EBITDA margin on gross bookings | B23: fraction | C23: =C19/C7 | D23: =D19/D7 | E23: =E19/E7 | F23: =F19/F7 | G23: =G19/G7 | H23: =H19/H7 | I23: =I19/I7 | J23: =J19/J7 | ... Q23: =Q19/Q7
A24: Freight adj. EBITDA margin on revenue | B24: fraction | C24: =C20/C13 | D24: =D20/D13 | E24: =E20/E13 | F24: =F20/F13 | G24: =G20/G13 | H24: =H20/H13 | I24: =I20/I13 | J24: =J20/J13 | ... Q24: =Q20/Q13
A25: Mobility gross bookings growth y/y | B25: fraction | H25: =(H6/C6)-1 | I25: =(I6/D6)-1 | J25: =(J6/E6)-1 | K25: =(K6/F6)-1 | M25: =(M6/H6)-1 | N25: =(N6/I6)-1 | O25: =(O6/J6)-1 | P25: =(P6/K6)-1 | R25: =(R6/M6)-1 | S25: =(S6/N6)-1 | T25: =Assumptions!$B$12+Assumptions!$B$9 | U25: =((T25-Assumptions!$B$9)*Assumptions!$B$8)+Assumptions!$B$9 | W25: =((U25-Assumptions!$B$9)*Assumptions!$B$8)+Assumptions!$B$9 | X25: =((W25-Assumptions!$B$9)*Assumptions!$B$8)+Assumptions!$B$9 | Y25: =((X25-Assumptions!$B$9)*Assumptions!$B$8)+Assumptions!$B$9 | Z25: =((Y25-Assumptions!$B$9)*Assumptions!$B$8)+Assumptions!$B$9
A26: Delivery gross bookings growth y/y | B26: fraction | H26: =(H7/C7)-1 | I26: =(I7/D7)-1 | J26: =(J7/E7)-1 | K26: =(K7/F7)-1 | M26: =(M7/H7)-1 | N26: =(N7/I7)-1 | O26: =(O7/J7)-1 | P26: =(P7/K7)-1 | R26: =(R7/M7)-1 | S26: =(S7/N7)-1 | T26: =Assumptions!$B$10+Assumptions!$B$9 | U26: =((T26-Assumptions!$B$9)*Assumptions!$B$8)+Assumptions!$B$9 | W26: =((U26-Assumptions!$B$9)*Assumptions!$B$8)+Assumptions!$B$9 | X26: =((W26-Assumptions!$B$9)*Assumptions!$B$8)+Assumptions!$B$9 | Y26: =((X26-Assumptions!$B$9)*Assumptions!$B$8)+Assumptions!$B$9 | Z26: =((Y26-Assumptions!$B$9)*Assumptions!$B$8)+Assumptions!$B$9
A27: Freight gross bookings growth y/y | B27: fraction | H27: =(H8/C8)-1 | I27: =(I8/D8)-1 | J27: =(J8/E8)-1 | K27: =(K8/F8)-1 | M27: =(M8/H8)-1 | N27: =(N8/I8)-1 | O27: =(O8/J8)-1 | P27: =(P8/K8)-1 | R27: =(R8/M8)-1 | S27: =(S8/N8)-1 | T27: =Assumptions!$B$11 | U27: =T27*Assumptions!$B$8 | W27: =U27*Assumptions!$B$8 | X27: =W27*Assumptions!$B$8 | Y27: =X27*Assumptions!$B$8 | Z27: =Y27*Assumptions!$B$8
A28: adjusted EBITDA margin on gross bookings | B28: fraction | C28: =C46/C9 | D28: =D46/D9 | E28: =E46/E9 | F28: =F46/F9 | G28: =G46/G9 | H28: =H46/H9 | I28: =I46/I9 | J28: =J46/J9 | ... AA28: =AA46/AA9
A29: costs before adj. EBITDA as a share of gross bookings | B29: fraction | C29: =(C47-C46)/C9 | D29: =(D47-D46)/D9 | E29: =(E47-E46)/E9 | F29: =(F47-F46)/F9 | G29: =(G47-G46)/G9 | H29: =(H47-H46)/H9 | I29: =(I47-I46)/I9 | J29: =(J47-J46)/J9 | ... S29: =(S47-S46)/S9 | T29: =MIN(MAX(IFERROR(IF(COUNT(O29)=1,O29,J29),J29)+T34,Assumptions!$B$5),Assumptions!$B$4) | U29: =MIN(MAX(IFERROR(IF(COUNT(P29)=1,P29,K29),K29)+U34,Assumptions!$B$5),Assumptions!$B$4) | V29: =(V47-V46)/V9 | W29: =MIN(MAX(IFERROR(IF(COUNT(R29)=1,R29,M29),M29)+W34,Assumptions!$B$5),Assumptions!$B$4) | X29: =MIN(MAX(IFERROR(IF(COUNT(S29)=1,S29,N29),N29)+X34,Assumptions!$B$5),Assumptions!$B$4) | Y29: =MIN(MAX(IFERROR(IF(COUNT(T29)=1,T29,O29),O29)+Y34,Assumptions!$B$5),Assumptions!$B$4) | Z29: =MIN(MAX(IFERROR(IF(COUNT(U29)=1,U29,P29),P29)+Z34,Assumptions!$B$5),Assumptions!$B$4) | AA29: =(AA47-AA46)/AA9
A30: trips growth y/y | B30: fraction | H30: =(H4/C4)-1 | I30: =(I4/D4)-1 | J30: =(J4/E4)-1 | K30: =(K4/F4)-1 | M30: =(M4/H4)-1 | N30: =(N4/I4)-1 | O30: =(O4/J4)-1 | P30: =(P4/K4)-1 | R30: =(R4/M4)-1 | S30: =(S4/N4)-1 | T30: =Assumptions!$B$26 | U30: =T30*Assumptions!$B$8 | W30: =U30*Assumptions!$B$8 | X30: =W30*Assumptions!$B$8 | Y30: =X30*Assumptions!$B$8 | Z30: =Y30*Assumptions!$B$8
A31: take rate mobility change y/y | B31: fraction | H31: =H14-C14 | I31: =I14-D14 | J31: =J14-E14 | K31: =K14-F14 | M31: =M14-H14 | N31: =N14-I14 | O31: =O14-J14 | P31: =P14-K14 | R31: =R14-M14 | S31: =S14-N14 | T31: =Assumptions!$B$24 | U31: =T31*Assumptions!$B$8 | W31: =U31*Assumptions!$B$8 | X31: =W31*Assumptions!$B$8 | Y31: =0 | Z31: =0
A32: take rate delivery change y/y | B32: fraction | H32: =H15-C15 | I32: =I15-D15 | J32: =J15-E15 | K32: =K15-F15 | M32: =M15-H15 | N32: =N15-I15 | O32: =O15-J15 | P32: =P15-K15 | R32: =R15-M15 | S32: =S15-N15 | T32: =Assumptions!$B$18 | U32: =T32*Assumptions!$B$8 | W32: =U32*Assumptions!$B$8 | X32: =W32*Assumptions!$B$8 | Y32: =0 | Z32: =0
A33: take rate freight change y/y | B33: fraction | H33: =H16-C16 | I33: =I16-D16 | J33: =J16-E16 | K33: =K16-F16 | M33: =M16-H16 | N33: =N16-I16 | O33: =O16-J16 | P33: =P16-K16 | R33: =R16-M16 | S33: =S16-N16 | T33: =Assumptions!$B$21 | U33: =T33*Assumptions!$B$8 | W33: =U33*Assumptions!$B$8 | X33: =W33*Assumptions!$B$8 | Y33: =0 | Z33: =0
A34: costs before adj. EBITDA as a share of gross bookings change y/y | B34: fraction | H34: =H29-C29 | I34: =I29-D29 | J34: =J29-E29 | K34: =K29-F29 | M34: =M29-H29 | N34: =N29-I29 | O34: =O29-J29 | P34: =P29-K29 | R34: =R29-M29 | S34: =S29-N29 | T34: =Assumptions!$B$6 | U34: =T34*Assumptions!$B$8 | W34: =U34*Assumptions!$B$8 | X34: =W34*Assumptions!$B$8 | Y34: =0 | Z34: =0
A35: Income statement
A36: adjusted EBITDA margin (on revenue) | B36: fraction | C36: =C46/C47 | D36: =D46/D47 | E36: =E46/E47 | F36: =F46/F47 | G36: =G46/G47 | H36: =H46/H47 | I36: =I46/I47 | J36: =J46/J47 | ... AA36: =AA46/AA47
A37: stock-based compensation | B37: USD millions | C37: 470 | D37: 504 | E37: 492 | F37: 469 | G37: =SUM(C37:F37) | H37: 484 | I37: 455 | J37: 438 | K37: 419 | L37: =SUM(H37:K37) | M37: 435 | N37: 475 | O37: 465 | P37: 451 | Q37: =SUM(M37:P37) | R37: 473 | S37: 550 | T37: =IFERROR(IF(COUNT(O37,O47)=2,O37/O47,Assumptions!$B$13),Assumptions!$B$13)*T47 | U37: =IFERROR(IF(COUNT(P37,P47)=2,P37/P47,Assumptions!$B$13),Assumptions!$B$13)*U47 | V37: =SUM(R37:U37) | W37: =IFERROR(IF(COUNT(R37,R47)=2,R37/R47,Assumptions!$B$13),Assumptions!$B$13)*W47 | X37: =IFERROR(IF(COUNT(S37,S47)=2,S37/S47,Assumptions!$B$13),Assumptions!$B$13)*X47 | Y37: =IFERROR(IF(COUNT(T37,T47)=2,T37/T47,Assumptions!$B$13),Assumptions!$B$13)*Y47 | Z37: =IFERROR(IF(COUNT(U37,U47)=2,U37/U47,Assumptions!$B$13),Assumptions!$B$13)*Z47 | AA37: =SUM(W37:Z37)
A38: depreciation and amortization | B38: USD millions | C38: 207 | D38: 208 | E38: 205 | F38: 203 | G38: =SUM(C38:F38) | H38: 190 | I38: 173 | J38: 179 | K38: 169 | L38: =SUM(H38:K38) | M38: 171 | N38: 175 | O38: 188 | P38: 185 | Q38: =SUM(M38:P38) | R38: 184 | S38: 188 | T38: =IFERROR(IF(COUNT(O38,O47)=2,O38/O47,Assumptions!$B$7),Assumptions!$B$7)*T47 | U38: =IFERROR(IF(COUNT(P38,P47)=2,P38/P47,Assumptions!$B$7),Assumptions!$B$7)*U47 | V38: =SUM(R38:U38) | W38: =IFERROR(IF(COUNT(R38,R47)=2,R38/R47,Assumptions!$B$7),Assumptions!$B$7)*W47 | X38: =IFERROR(IF(COUNT(S38,S47)=2,S38/S47,Assumptions!$B$7),Assumptions!$B$7)*X47 | Y38: =IFERROR(IF(COUNT(T38,T47)=2,T38/T47,Assumptions!$B$7),Assumptions!$B$7)*Y47 | Z38: =IFERROR(IF(COUNT(U38,U47)=2,U38/U47,Assumptions!$B$7),Assumptions!$B$7)*Z47 | AA38: =SUM(W38:Z38)
A39: GAAP operating income | B39: USD millions | C39: -262 | D39: 326 | E39: 394 | F39: 652 | G39: =SUM(C39:F39) | H39: 172 | I39: 796 | J39: 1061 | K39: 770 | L39: =SUM(H39:K39) | M39: 1228 | N39: 1450 | O39: 1113 | P39: 1774 | Q39: =SUM(M39:P39) | R39: 1923 | S39: 1890 | T39: =(T46-T37)-T38 | U39: =(U46-U37)-U38 | V39: =SUM(R39:U39) | W39: =(W46-W37)-W38 | X39: =(X46-X37)-X38 | Y39: =(Y46-Y37)-Y38 | Z39: =(Z46-Z37)-Z38 | AA39: =SUM(W39:Z39)
A40: other adjustments (adj. EBITDA bridge to operating income) | B40: USD millions | C40: =((C46-C37)-C38)-C39 | D40: =((D46-D37)-D38)-D39 | E40: =((E46-E37)-E38)-E39 | F40: =((F46-F37)-F38)-F39 | G40: =SUM(C40:F40) | H40: =((H46-H37)-H38)-H39 | I40: =((I46-I37)-I38)-I39 | J40: =((J46-J37)-J38)-J39 | K40: =((K46-K37)-K38)-K39 | L40: =SUM(H40:K40) | M40: =((M46-M37)-M38)-M39 | N40: =((N46-N37)-N38)-N39 | O40: =((O46-O37)-O38)-O39 | P40: =((P46-P37)-P38)-P39 | Q40: =SUM(M40:P40) | R40: =((R46-R37)-R38)-R39 | S40: =((S46-S37)-S38)-S39 | T40: =((T46-T37)-T38)-T39 | U40: =((U46-U37)-U38)-U39 | V40: =SUM(R40:U40) | W40: =((W46-W37)-W38)-W39 | X40: =((X46-X37)-X38)-X39 | Y40: =((Y46-Y37)-Y38)-Y39 | Z40: =((Z46-Z37)-Z38)-Z39 | AA40: =SUM(W40:Z40)
...

Sheet Assumptions
A1: assumption | B1: value
A2: buybacks_q | B2: 1726
A3: capex.ratio | B3: 0.0055769823
A4: cost_to_gb.hi | B4: 0.25181119
A5: cost_to_gb.lo | B5: 0.17599462
A6: cost_to_gb.shift0 | B6: -0.028698109
A7: d_and_a.ratio | B7: 0.013489779
A8: fade | B8: 0.9
A9: gb_g_adj | B9: -0.051264189
A10: gb_g_delivery.g0 | B10: 0.26359621
A11: gb_g_freight.g0 | B11: 0.2468254
A12: gb_g_mobility.g0 | B12: 0.21993098
A13: sbc.ratio | B13: 0.035109638
... A26: trips_g.g0 | B26: 0.18329253

Sheet Summary
A1: item | B1: value
A2: rating (draft) | B2: Buy
A3: price | B3: 68.18
A4: price date | B4: 2026-08-05
A5: 12-month price target | B5: 83.622622
A6: return | B6: 0.22649783
A7: market cap (USD millions) | B7: 139784.34
A8: EV (USD millions) | B8: 147116.34
A9: net debt (USD millions) | B9: 7332
A10: diluted shares (millions) | B10: 2050.225
A11: WACC | B11: 0.094984214
A12: parity | B12: 750/750

Sheet Scenarios
A1: scenario and line | B1: year | C1: value
A2: base revenue | B2: FY2026 | C2: 57297.21
A3: base revenue | B3: FY2027 | C3: 63872.547
A4: base adj_ebitda | B4: FY2026 | C4: 11319.223
A5: base adj_ebitda | B5: FY2027 | C5: 15237.707
A6: base eps_diluted | B6: FY2026 | C6: 3.3439925
A7: base eps_diluted | B7: FY2027 | C7: 5.5482624
A8: base free_cash_flow | B8: FY2026 | C8: 10447.764
A9: base free_cash_flow | B9: FY2027 | C9: 13666.349
A10: bear revenue | B10: FY2026 | C10: 56186.31
A11: bear revenue | B11: FY2027 | C11: 61185.237
A12: bear adj_ebitda | B12: FY2026 | C12: 11017.251
A13: bear adj_ebitda | B13: FY2027 | C13: 14682.74
... A33: weighted free_cash_flow | B33: FY2027 | C33: 14006.351

Sheet Valuation
A1: item | B1: value
A2: peer 2027E EV/EBITDA CART | B2: 8.1181106
A3: peer 2027E EV/EBITDA DASH | B3: 19.177384
A4: peer 2027E EV/EBITDA LYFT | B4: 7.3672749
A5: peer median | B5: 8.1181106
A6: rf | B6: 0.0463
A7: rf_id | B7: macro:DGS10:2026-08-04
A8: erp | B8: 0.0428
A9: erp_id | B9: erp:damodaran:2026-08-01
A10: beta | B10: 1.1374816
A11: beta_months | B11: 60
A12: ke | B12: 0.094984214
A13: kd | B13: 0.036312191
A14: debt_weight | B14: 0.083425493
A15: wacc | B15: 0.094984214
A16: base adj_ebitda | B16: 15237.707
A17: base target_multiple | B17: 8.1181106
A18: base multiple_outside_peer_range | B18: FALSE
A19: base multiple_pt | B19: 56.759325
A20: base dcf_ev | B20: 246810.62
A21: base dcf_pt | B21: 116.80602
A22: base dcf_used | B22: TRUE
A23: base terminal_share | B23: 0.60397552
A24: base price_target | B24: 80.778003
A25: bear adj_ebitda | B25: 14682.74
A26: bear target_multiple | B26: 6.900394
A27: bear multiple_outside_peer_range | B27: TRUE
A28: bear multiple_pt | B28: 45.841158
A29: bear dcf_ev | B29: 215608.03
A30: bear dcf_pt | B30: 101.58691
A31: bear dcf_used | B31: TRUE
A32: bear terminal_share | B32: 0.58999112
A33: bear price_target | B33: 68.13946
A34: bull adj_ebitda | B34: 17306.587
A35: bull target_multiple | B35: 9.3358272
A36: bull multiple_outside_peer_range | B36: FALSE
A37: bull multiple_pt | B37: 75.230429
A38: bull dcf_ev | B38: 313106.49
A39: bull dcf_pt | B39: 149.14192
A40: bull dcf_used | B40: TRUE
...

Sheet Revisions
A1: line | B1: old | C1: new | D1: type | E1: confidence

Sheet Checks
A1: check | B1: status | C1: tested | D1: failures | E1: skipped
A2: balance | B2: pass | C2: 34 | E2: 0
A3: quarters_sum | B3: pass | C3: 24 | E3: 3
A4: q4_ties | B4: pass | C4: 34 | E4: 0
A5: take_rate | B5: pass | C5: 56 | E5: 0
A6: segments_sum | B6: pass | C6: 65 | E6: 10
A7: no_future_input | B7: pass | C7: 427 | E7: 0
A8: formula_only | B8: pass | C8: 276 | E8: 0

Sheet Log
A1: id | B1: kind | C1: label or severity | D1: value or item | E1: source
A2: E-1 | B2: evidence | C2: Price | D2: $68.18 | E2: px:UBER:2026-08-05
A3: E-2 | B3: evidence | C3: 12-month price target | D3: $83.62 | E3: model:UBER:2026-08-06:val-base:price_target
A4: E-3 | B4: evidence | C4: Implied return | D4: +22.6% | E4: model:UBER:2026-08-06:val-base:return
A5: E-4 | B5: evidence | C5: Draft rating | D5: Buy | E5: model:UBER:2026-08-06:val-base:rating
A6: E-5 | B6: evidence | C6: Market cap | D6: $139.8B | E6: computed: price × shares
A7: E-6 | B7: evidence | C7: Enterprise value | D7: $147.1B | E7: computed: market cap + net debt
A8: E-7 | B8: evidence | C8: 52-week low | D8: $65.94 | E8: px
A9: E-8 | B9: evidence | C9: 52-week high | D9: $100.10 | E9: px
A10: E-9 | B10: evidence | C10: 2026Q2 Revenue actual | D10: $14.2B | E10: q:UBER:revenue:2026Q2
A11: E-10 | B11: evidence | C11: 2026Q2 Revenue our estimate | D11: $14.1B | E11: model:UBER:2026-05-07:base:revenue.2026Q2
A12: E-11 | B12: evidence | C12: 2026Q2 Revenue variance vs our estimate | D12: +0.8% | E12: computed from F-9, F-10
... A163: E-162 | B163: evidence | C163: Sell threshold return | D163: -10.0% | E163: research.yaml
A164: X-01 | B164: exception | C164: info | D164: shares_diluted missing in 2023Q4, 2024Q4, 2025Q4
A165: X-02 | B165: exception | C165: info | D165: buybacks missing in 2023Q1, 2023Q2
A166: X-03 | B166: exception | C166: info | D166: total_assets missing in 2026Q3, 2026Q4, 2027Q1, 2027Q2, 2027Q3, 2027Q4
A167: X-04 | B167: exception | C167: info | D167: total_liabilities missing in 2026Q3, 2026Q4, 2027Q1, 2027Q2, 2027Q3, 2027Q4
A168: X-05 | B168: exception | C168: info | D168: mezzanine missing in 2026Q3, 2026Q4, 2027Q1, 2027Q2, 2027Q3, 2027Q4
A169: X-06 | B169: exception | C169: info | D169: equity_total missing in 2026Q3, 2026Q4, 2027Q1, 2027Q2, 2027Q3, 2027Q4
A170: X-07 | B170: exception | C170: info | D170: liabilities_and_equity missing in 2026Q3, 2026Q4, 2027Q1, 2027Q2, 2027Q3, 2027Q4
A171: X-08 | B171: exception | C171: info | D171: mapcs missing in 2026Q3, 2026Q4, 2027Q1, 2027Q2, 2027Q3, 2027Q4
A172: X-09 | B172: exception | C172: info | D172: adj_ebitda_mobility missing in 2026Q1, 2026Q2, 2026Q3, 2026Q4, 2027Q1, 2027Q2, 2027Q3, 2027Q4
A173: X-10 | B173: exception | C173: info | D173: adj_ebitda_delivery missing in 2026Q1, 2026Q2, 2026Q3, 2026Q4, 2027Q1, 2027Q2, 2027Q3, 2027Q4
A174: X-11 | B174: exception | C174: info | D174: adj_ebitda_freight missing in 2026Q1, 2026Q2, 2026Q3, 2026Q4, 2027Q1, 2027Q2, 2027Q3, 2027Q4
A175: X-12 | B175: exception | C175: info | D175: adj_ebitda_corporate missing in 2026Q1, 2026Q2, 2026Q3, 2026Q4, 2027Q1, 2027Q2, 2027Q3, 2027Q4
... A180: X-17 | B180: exception | C180: info | D180: bear target multiple 6.9x outside the peer range
