Workbook

Sheet README
A1: UBER Q2 2026 earnings update: model-change workbook (example)
A3: Illustrative: every figure is invented to show the format. Not investment advice.
A5: Purpose: companion to the example note in docs/JUNIOR_SELL_SIDE_EQUITY_RESEARCH_AGENT_SPEC.md, section 2.3.
A6: A senior analyst opens it to see exactly what moved in the model and why.
A8: Colour code: blue = hard-coded input, black = formula, green = link to another tab.
A9: Change a blue input and every dependent number recalculates.
A11: Tabs
A12: Summary old vs. new estimates, change, source, type, confidence
A13: Bridge each revision split by driver, tied back to Summary
A14: Assumptions every assumption with basis (reported, derived, analyst-imposed), confidence, date
A15: Model Q2 2026 KPIs, segments, cash flow, guidance, Q3E, annual summary (excerpt)
A16: Scenarios bear / base / bull, probability-weighted value, sensitivities
... A23: instead of linking to a prior-version tab, and Mobility / Delivery sensitivities are inputs.

Sheet Summary
A1: Estimate changes: old vs. new, $B
A2: Illustrative: every figure is invented to show the format. Not investment advice. Old values come from the prior model version (kept as its own tab in a real run). % change uses the old value as denominator.
A4: Metric | B4: Old | C4: New | D4: Change ($B) | E4: Change (%) | F4: Source of change | G4: Type | H4: Confidence
A5: Q3 2026E adj. EBITDA | B5: 2.2 | C5: =Assumptions!$C$21 -> 2.28 | D5: =C5-B5 -> 0.08 | E5: =C5/B5-1 -> 0.036363636 | F5: Guidance + assumption | G5: Recurring | H5: Medium
A6: FY2026E revenue | B6: 50.1 | C6: =Model!D49 -> 51 | D6: =C6-B6 -> 0.9 | E6: =C6/B6-1 -> 0.017964072 | F6: Reported + assumption | G6: Mixed | H6: Medium
A7: FY2026E adj. EBITDA | B7: 8.6 | C7: =Model!D51 -> 8.9 | D7: =C7-B7 -> 0.3 | E7: =C7/B7-1 -> 0.034883721 | F7: Reported + assumption | G7: Mixed | H7: Medium
A8: FY2027E adj. EBITDA | B8: 9.4 | C8: =Model!E51 -> 9.7 | D8: =C8-B8 -> 0.3 | E8: =C8/B8-1 -> 0.031914894 | F8: Analyst assumption | G8: Recurring | H8: Medium
A9: FY2028E adj. EBITDA | B9: 11 | C9: =Model!F51 -> 11.4 | D9: =C9-B9 -> 0.4 | E9: =C9/B9-1 -> 0.036363636 | F9: Analyst assumption | G9: Recurring | H9: Low

Sheet Bridge
A1: Revision bridge, $B
A2: Illustrative: every figure is invented to show the format. Not investment advice. Every change is split by driver and by source of the change.
A4: Estimate | B4: Driver | C4: Source type | D4: Change ($B) | E4: Nature
A5: Q3 2026E adj. EBITDA | B5: Q2 beat carried forward | C5: Reported | D5: 0.03 | E5: Recurring
A6: Q3 2026E adj. EBITDA | B6: Delivery margin | C6: Analyst assumption | D6: 0.05 | E6: Recurring
A7: FY2026E revenue | B7: Q2 beat (actual - our estimate) | C7: Reported | D7: =Model!B7-Model!E7 -> 0.3 | E7: Timing
A8: FY2026E revenue | B8: Q3-Q4 carry-through | C8: Analyst assumption | D8: 0.6 | E8: Recurring
A9: FY2026E adj. EBITDA | B9: Q2 beat | C9: Reported | D9: 0.1 | E9: Timing
A10: FY2026E adj. EBITDA | B10: Q3 Delivery margin | C10: Analyst assumption | D10: 0.08 | E10: Recurring
A11: FY2026E adj. EBITDA | B11: Q4 Delivery margin | C11: Analyst assumption | D11: 0.12 | E11: Recurring
A12: FY2027E adj. EBITDA | B12: Mobility growth | C12: Analyst assumption | D12: 0.15 | E12: Recurring
A13: FY2027E adj. EBITDA | B13: Delivery margin | C13: Analyst assumption | D13: 0.1 | E13: Recurring
A14: FY2027E adj. EBITDA | B14: Operating leverage | C14: Analyst assumption | D14: 0.05 | E14: Recurring
A15: FY2028E adj. EBITDA | B15: Mobility growth | C15: Analyst assumption | D15: 0.18 | E15: Recurring
A16: FY2028E adj. EBITDA | B16: Delivery margin | C16: Analyst assumption | D16: 0.1 | E16: Recurring
A17: FY2028E adj. EBITDA | B17: Operating leverage | C17: Analyst assumption | D17: 0.12 | E17: Recurring
A19: Tie-out to Summary
A20: Estimate | B20: Sum of bridge | C20: Summary change | D20: Difference
A21: Q3 2026E adj. EBITDA | B21: =SUMIF($A$5:$A$17,A21,$D$5:$D$17) -> 0.08 | C21: =Summary!D5 -> 0.08 | D21: =B21-C21 -> 3.7470027e-16
A22: FY2026E revenue | B22: =SUMIF($A$5:$A$17,A22,$D$5:$D$17) -> 0.9 | C22: =Summary!D6 -> 0.9 | D22: =B22-C22 -> 0
A23: FY2026E adj. EBITDA | B23: =SUMIF($A$5:$A$17,A23,$D$5:$D$17) -> 0.3 | C23: =Summary!D7 -> 0.3 | D23: =B23-C23 -> 0
A24: FY2027E adj. EBITDA | B24: =SUMIF($A$5:$A$17,A24,$D$5:$D$17) -> 0.3 | C24: =Summary!D8 -> 0.3 | D24: =B24-C24 -> 0
A25: FY2028E adj. EBITDA | B25: =SUMIF($A$5:$A$17,A25,$D$5:$D$17) -> 0.4 | C25: =Summary!D9 -> 0.4 | D25: =B25-C25 -> 0

Sheet Assumptions
A1: Assumptions register
A2: Illustrative: every figure is invented to show the format. Not investment advice. Blue = input, black = formula, green = link to another tab.
A4: ID | B4: Assumption | C4: Value | D4: Unit | E4: Basis | F4: Confidence | G4: Model variables affected | H4: Last updated
A5: A-01 | B5: Share price (2026-08-05 close) | C5: 80 | D5: $ | E5: reported | F5: High | G5: Market cap, EV, return | H5: 2026-08-06
A6: A-02 | B6: Diluted shares | C6: 2.0625 | D6: B | E6: reported | F6: High | G6: Market cap, per-share values | H6: 2026-08-06
A7: A-03 | B7: Quoted market cap (tie-out) | C7: 165 | D7: $B | E7: reported | F7: High | G7: Check only | H7: 2026-08-06
A8: A-04 | B8: Quoted enterprise value (tie-out) | C8: 168 | D8: $B | E8: reported | F8: High | G8: Check only | H8: 2026-08-06
A9: A-05 | B9: Net debt | C9: 3 | D9: $B | E9: reported | F9: High | G9: EV to equity bridge | H9: 2026-08-06
A10: A-06 | B10: Target EV / 2027E adj. EBITDA | C10: 19 | D10: x | E10: analyst-imposed | F10: Medium | G10: Multiple price target | H10: 2026-08-06
A11: A-07 | B11: Weight: multiple method | C11: 0.6 | D11: % | E11: analyst-imposed | F11: Medium | G11: Blended price target | H11: 2026-08-06
A12: A-08 | B12: Weight: DCF | C12: =1-C11 -> 0.4 | D12: % | E12: derived | F12: Medium | G12: Blended price target | H12: 2026-08-06
A13: A-09 | B13: Buy threshold (12-month return) | C13: 0.15 | D13: % | E13: analyst-imposed | F13: High | G13: Rating | H13: 2026-08-06
A14: A-10 | B14: Sell threshold (12-month return) | C14: -0.1 | D14: % | E14: analyst-imposed | F14: High | G14: Rating | H14: 2026-08-06
A15: A-11 | B15: Scenario weight: bear | C15: 0.25 | D15: % | E15: analyst-imposed | F15: Medium | G15: Probability-weighted value | H15: 2026-08-06
A16: A-12 | B16: Scenario weight: base | C16: 0.5 | D16: % | E16: analyst-imposed | F16: Medium | G16: Probability-weighted value | H16: 2026-08-06
A17: A-13 | B17: Scenario weight: bull | C17: 0.25 | D17: % | E17: analyst-imposed | F17: Medium | G17: Probability-weighted value | H17: 2026-08-06
A18: A-14 | B18: Take rate, Q2 2026 (revenue / gross bookings) | C18: =Model!B9 -> 0.26819127 | D18: % | E18: derived | F18: High | G18: Q3E revenue | H18: 2026-08-06
A19: A-15 | B19: Take rate, Q3 2026E (held flat) | C19: =C18 -> 0.26819127 | D19: % | E19: analyst-imposed | F19: Medium | G19: Q3E revenue, 2027E sensitivity | H19: 2026-08-06
A20: A-16 | B20: Q3 2026E gross bookings | C20: 51.8 | D20: $B | E20: analyst-imposed | F20: Medium | G20: Q3E revenue | H20: 2026-08-06
A21: A-17 | B21: Q3 2026E adj. EBITDA | C21: 2.28 | D21: $B | E21: analyst-imposed | F21: Medium | G21: Q3E, FY2026E | H21: 2026-08-06
A22: A-18 | B22: Variance flag vs guidance midpoint: revenue / bookings | C22: 0.02 | D22: % | E22: analyst-imposed | F22: High | G22: Check | H22: 2026-08-06
A23: A-19 | B23: Variance flag vs guidance midpoint: adj. EBITDA | C23: 0.05 | D23: % | E23: analyst-imposed | F23: High | G23: Check | H23: 2026-08-06
A24: A-20 | B24: Growth fade factor per year | C24: 0.9 | D24: x | E24: analyst-imposed | F24: Medium | G24: DCF cash-flow growth | H24: 2026-08-06
A25: A-21 | B25: Terminal growth | C25: 0.03 | D25: % | E25: analyst-imposed | F25: Medium | G25: DCF | H25: 2026-08-06
A26: A-22 | B26: Flow-through of incremental revenue to adj. EBITDA | C26: 0.7 | D26: % | E26: analyst-imposed | F26: Low | G26: Take-rate sensitivity | H26: 2026-08-06

Sheet Model
A1: Model excerpt: UBER Q2 2026 (Apr-Jun), $B unless noted
A2: Illustrative: every figure is invented to show the format. Not investment advice. Excerpt only: the full model is three statements by quarter, formulas only.
A4: Metric | B4: Q2 2026A | C4: Q2 2025A | D4: Y/Y | E4: Our est. | F4: Var. vs est. | G4: Guide mid | H4: Var. vs mid | I4: Source
A5: Trips (B) | B5: 3.4 | C5: 2.93 | D5: =B5/C5-1 -> 0.16040956 | E5: 3.3 | F5: =B5/E5-1 -> 0.03030303 | G5: n/a | H5: n/a | I5: 8-K Ex. 99.1 (Log E-01 to E-04)
A6: Gross bookings | B6: 48.1 | C6: 40.4 | D6: =B6/C6-1 -> 0.19059406 | E6: 47.5 | F6: =B6/E6-1 -> 0.012631579 | G6: =D35 -> 47 | H6: =B6/G6-1 -> 0.023404255 | I6: 8-K Ex. 99.1 (Log E-01 to E-04)
A7: Revenue | B7: 12.9 | C7: 11 | D7: =B7/C7-1 -> 0.17272727 | E7: 12.6 | F7: =B7/E7-1 -> 0.023809524 | G7: n/a | H7: n/a | I7: 8-K Ex. 99.1 (Log E-01 to E-04)
A8: Adjusted EBITDA | B8: 2.1 | C8: 1.6 | D8: =B8/C8-1 -> 0.3125 | E8: 2 | F8: =B8/E8-1 -> 0.05 | G8: =D36 -> 2 | H8: =B8/G8-1 -> 0.05 | I8: 8-K Ex. 99.1 (Log E-01 to E-04)
A9: Take rate (revenue / gross bookings) | B9: =B7/B6 -> 0.26819127 | C9: =C7/C6 -> 0.27227723 | D9: =(B9-C9)*10000 -> -40.859595
A10: Bookings per trip ($) | B10: =B6/B5 -> 14.147059 | C10: =C6/C5 -> 13.788396 | D10: =B10/C10-1 -> 0.026011939
A12: Segment gross bookings
A13: Mobility | B13: 24.5 | C13: 20.9 | D13: =B13/C13-1 -> 0.1722488
A14: Delivery | B14: 21.8 | C14: 18 | D14: =B14/C14-1 -> 0.21111111
A15: Freight | B15: 1.8 | C15: 1.5 | D15: =B15/C15-1 -> 0.2
A16: Total (sum of segments) | B16: =SUM(B13:B15) -> 48.1 | C16: =SUM(C13:C15) -> 40.4 | D16: =B16/C16-1 -> 0.19059406
A18: Segment adjusted EBITDA
A19: Mobility | B19: 1.5 | I19: 10-Q segment note (Log E-07)
A20: Delivery | B20: 0.8 | C20: 0.59
A21: Freight | B21: 0.02
A22: Corporate and other | B22: -0.22
A23: Total (sum of segments) | B23: =SUM(B19:B22) -> 2.1
A24: Delivery EBITDA / Delivery bookings | B24: =B20/B14 -> 0.036697248 | C24: =C20/C14 -> 0.032777778 | D24: =(B24-C24)*10000 -> 39.194699
A26: Cash flow and reconciliation
A27: Operating cash flow | B27: 2.4
A28: Capital expenditure | B28: 0.1
A29: Free cash flow | B29: =B27-B28 -> 2.3
A30: FCF / adj. EBITDA | B30: =B29/B8 -> 1.0952381
A31: Share-based compensation | B31: 0.45
A32: Adj. EBITDA per 10-Q segment note (rounding test) | B32: 2.08 | I32: Log E-08, X-01
A34: Item | B34: Low | C34: High | D34: Midpoint | E34: Actual / our forecast | F34: Var. vs mid | G34: Flag threshold | H34: Flag
A35: Q2 gross bookings guide (prior quarter) | B35: 46 | C35: 48 | D35: =AVERAGE(B35:C35) -> 47 | E35: =B6 -> 48.1 | F35: =E35/D35-1 -> 0.023404255
A36: Q2 adj. EBITDA guide (prior quarter) | B36: 1.9 | C36: 2.1 | D36: =AVERAGE(B36:C36) -> 2 | E36: =B8 -> 2.1 | F36: =E36/D36-1 -> 0.05
A37: Q3 gross bookings guide (new) | B37: 50.5 | C37: 52 | D37: =AVERAGE(B37:C37) -> 51.25 | E37: =Assumptions!$C$20 -> 51.8 | F37: =E37/D37-1 -> 0.010731707 | G37: =Assumptions!$C$22 -> 0.02 | H37: =IF(ABS(F37)>G37,"WRITTEN REASON REQUIRED","ok") -> ok | I37: 8-K Ex. 99.1 outlook (Log E-05, E-06)
A38: Q3 adj. EBITDA guide (new) | B38: 2.2 | C38: 2.3 | D38: =AVERAGE(B38:C38) -> 2.25 | E38: =Assumptions!$C$21 -> 2.28 | F38: =E38/D38-1 -> 0.013333333 | G38: =Assumptions!$C$23 -> 0.05 | H38: =IF(ABS(F38)>G38,"WRITTEN REASON REQUIRED","ok") -> ok
A39: Q3 guide midpoint vs Q2 actual: gross bookings | B39: =D37/B6-1 -> 0.065488565
A40: Q3 guide midpoint vs Q2 actual: adj. EBITDA | B40: =D38/B8-1 -> 0.071428571
A42: Q3 2026E forecast
A43: Gross bookings | B43: =Assumptions!$C$20 -> 51.8
A44: Take rate | B44: =Assumptions!$C$19 -> 0.26819127
A45: Revenue (bookings x take rate) | B45: =B43*B44 -> 13.892308
A46: Adjusted EBITDA | B46: =Assumptions!$C$21 -> 2.28
...

Sheet Scenarios
A1: Scenarios and sensitivities
A2: Illustrative: every figure is invented to show the format. Not investment advice.
A4: Scenario | B4: Price target ($) | C4: Weight | D4: Return vs price | E4: Key assumptions
A5: Bear | B5: 70 | C5: =Assumptions!$C$15 -> 0.25 | D5: =B5/Assumptions!$C$5-1 -> -0.125 | E5: Take rate -75 bps vs. base; Mobility growth 12%; 16x
A6: Base | B6: =Valuation!B35 -> 95 | C6: =Assumptions!$C$16 -> 0.5 | D6: =B6/Assumptions!$C$5-1 -> 0.1875 | E6: Estimates in Summary; 19x
A7: Bull | B7: 120 | C7: =Assumptions!$C$17 -> 0.25 | D7: =B7/Assumptions!$C$5-1 -> 0.5 | E7: Mobility growth 20%; Delivery margin +100 bps; 22x
A8: Probability-weighted | B8: =SUMPRODUCT(B5:B7,C5:C7) -> 95 | C8: =SUM(C5:C7) -> 1 | D8: =B8/Assumptions!$C$5-1 -> 0.1875
A10: Sensitivity of 2027E (one shock at a time)
A11: Risk | B11: Shock | C11: 2027E adj. EBITDA ($B) | D11: % of 2027E EBITDA | E11: Price target ($) | F11: PT % | G11: Evidence
A12: Take-rate compression | B12: -0.005 | C12: =B12*B19*Assumptions!$C$26 -> -0.74387209 | D12: =C12/Model!$E$51 -> -0.076687845 | E12: =C12*Assumptions!$C$10/Assumptions!$C$6*Assumptions!$C$11+Valuation!$B$33*D12*Assumptions!$C$12 -> -7.3580559 | F12: =E12/Valuation!$B$35 -> -0.07745322 | G12: Current: take rate down 40 bps y/y
A13: Slower Mobility growth (per 1 pt) | B13: -0.01 | C13: -0.06 | D13: =C13/Model!$E$51 -> -0.006185567 | E13: =C13*Assumptions!$C$10/Assumptions!$C$6*Assumptions!$C$11+Valuation!$B$33*D13*Assumptions!$C$12 -> -0.59349363 | F13: =E13/Valuation!$B$35 -> -0.0062473014 | G13: Hypothetical
A14: Delivery margin deterioration | B14: -0.005 | C14: -0.5 | D14: =C14/Model!$E$51 -> -0.051546392 | E14: =C14*Assumptions!$C$10/Assumptions!$C$6*Assumptions!$C$11+Valuation!$B$33*D14*Assumptions!$C$12 -> -4.9457803 | F14: =E14/Valuation!$B$35 -> -0.052060845 | G14: Hypothetical
A15: Regulation | C15: Not quantified | G15: New 10-Q risk factor
A16: AV competition | C16: Scenario only | G16: Qualitative only
A18: Helper
A19: 2027E gross bookings = revenue / take rate ($B) | B19: =Model!E49/Assumptions!$C$19 -> 212.53488
A20: Method: EBITDA change x target multiple / shares x multiple weight, plus DCF value scaled by the % EBITDA change x DCF weight.
A21: Mobility and Delivery EBITDA changes are inputs here: a full run takes them from the segment model.

Sheet Valuation
A1: Valuation: UBER
A2: Illustrative: every figure is invented to show the format. Not investment advice.
A4: Market data (2026-08-05 close)
A5: Share price ($) | B5: =Assumptions!$C$5 -> 80
A6: Diluted shares (B) | B6: =Assumptions!$C$6 -> 2.0625
A7: Market cap ($B) | B7: =B5*B6 -> 165
A8: Net debt ($B) | B8: =Assumptions!$C$9 -> 3
A9: Enterprise value ($B) | B9: =B7+B8 -> 168
A10: 2027E adj. EBITDA ($B) | B10: =Model!E51 -> 9.7
A11: Current EV / 2027E adj. EBITDA | B11: =B9/B10 -> 17.319588
A13: Peers: 2027E EV / adj. EBITDA
A14: LYFT | B14: 13
A15: CART | B15: 19
A16: DASH | B16: 20
A17: Median | B17: =MEDIAN(B14:B16) -> 19
A18: Low | B18: =MIN(B14:B16) -> 13
A19: High | B19: =MAX(B14:B16) -> 20
A20: Peers (n) | B20: =COUNT(B14:B16) -> 3
A22: Multiple method
A23: Target multiple | B23: =Assumptions!$C$10 -> 19
A24: Target EV ($B) | B24: =B23*B10 -> 184.3
A25: Less net debt ($B) | B25: =B8 -> 3
A26: Equity value ($B) | B26: =B24-B25 -> 181.3
A27: Value per share ($) | B27: =B26/B6 -> 87.90303
A28: Target multiple vs peer range | B28: =IF(AND(B23>=B18,B23<=B19),"inside range","FLAG: outside range") -> inside range
A29: Target multiple vs peer median | B29: =B23/B17-1 -> 0
A31: Price target and rating | B31: Value per share ($) | C31: Weight
A32: Multiple method | B32: =B27 -> 87.90303 | C32: =Assumptions!$C$11 -> 0.6
A33: DCF | B33: =DCF!B28 -> 105.83398 | C33: =Assumptions!$C$12 -> 0.4
A34: Blended value | B34: =B32*C32+B33*C33 -> 95.07541
A35: 12-month price target ($) | B35: =ROUND(B34,0) -> 95
A36: 12-month return vs price | B36: =B35/B5-1 -> 0.1875
A37: Draft rating | B37: =IF(B36>=Assumptions!$C$13,"Buy",IF(B36<=Assumptions!$C$14,"Sell","Hold")) -> Buy
A38: DCF terminal value share of EV | B38: =DCF!B25 -> 0.60852443

Sheet DCF
A1: DCF: UBER, $B unless noted
A2: Illustrative: every figure is invented to show the format. Not investment advice.
A4: Risk-free rate (FRED DGS10) | B4: 0.042
A5: Beta (5-year regression) | B5: 1.3
A6: Equity risk premium (Damodaran) | B6: 0.045
A7: Cost of equity (CAPM) | B7: =B4+B5*B6 -> 0.1005
A8: WACC (treated as all-equity: debt is small) | B8: =B7 -> 0.1005
A9: Terminal growth | B9: =Assumptions!$C$25 -> 0.03
A10: Year-2 UFCF growth | B10: 0.2
A11: Growth fade factor | B11: =Assumptions!$C$24 -> 0.9
A12: Year-1 unlevered FCF (SBC treated as a cost) | B12: 7.65
A14: Year | B14: 1 | C14: 2 | D14: 3 | E14: 4 | F14: 5 | G14: 6 | H14: 7 | I14: 8 | J14: 9 | K14: 10
A15: Phase | B15: modeled | C15: modeled | D15: modeled | E15: faded | F15: faded | G15: faded | H15: faded | I15: faded | J15: faded | K15: faded
A16: UFCF growth | C16: =$B$10 -> 0.2 | D16: =C16*$B$11 -> 0.18 | E16: =D16*$B$11 -> 0.162 | F16: =E16*$B$11 -> 0.1458 | G16: =F16*$B$11 -> 0.13122 | H16: =G16*$B$11 -> 0.118098 | I16: =H16*$B$11 -> 0.1062882 | J16: =I16*$B$11 -> 0.09565938 | K16: =J16*$B$11 -> 0.086093442
A17: Unlevered FCF | B17: =$B$12 -> 7.65 | C17: =B17*(1+C16) -> 9.18 | D17: =C17*(1+D16) -> 10.8324 | E17: =D17*(1+E16) -> 12.587249 | F17: =E17*(1+F16) -> 14.42247 | G17: =F17*(1+G16) -> 16.314986 | H17: =G17*(1+H16) -> 18.241753 | I17: =H17*(1+I16) -> 20.180637 | J17: =I17*(1+J16) -> 22.111104 | K17: =J17*(1+K16) -> 24.014725
A18: Discount factor | B18: =1/(1+$B$8)^B14 -> 0.90867787 | C18: =1/(1+$B$8)^C14 -> 0.82569548 | D18: =1/(1+$B$8)^D14 -> 0.75029121 | E18: =1/(1+$B$8)^E14 -> 0.68177302 | F18: =1/(1+$B$8)^F14 -> 0.61951206 | G18: =1/(1+$B$8)^G14 -> 0.5629369 | H18: =1/(1+$B$8)^H14 -> 0.51152831 | I18: =1/(1+$B$8)^I14 -> 0.46481445 | ... K18: =1/(1+$B$8)^K14 -> 0.38379519
A19: Present value | B19: =B17*B18 -> 6.9513857 | C19: =C17*C18 -> 7.5798845 | D19: =D17*D18 -> 8.1274545 | E19: =E17*E18 -> 8.5816467 | F19: =F17*F18 -> 8.9348939 | G19: =G17*G18 -> 9.1843078 | H19: =H17*H18 -> 9.3311732 | I19: =I17*I18 -> 9.3802515 | ... K19: =K17*K18 -> 9.2167359
A21: Sum of PV, years 1-10 | B21: =SUM(B19:K19) -> 86.626726
A22: Terminal value (year 10) | B22: =K17*(1+B9)/(B8-B9) -> 350.85342
A23: PV of terminal value | B23: =B22*K18 -> 134.65586
A24: Enterprise value | B24: =B21+B23 -> 221.28258
A25: Terminal value share of EV | B25: =B23/B24 -> 0.60852443
A26: Less net debt | B26: =Assumptions!$C$9 -> 3
A27: Equity value | B27: =B24-B26 -> 218.28258
A28: DCF value per share ($) | B28: =B27/Assumptions!$C$6 -> 105.83398
A30: Price per share ($): WACC (down) x terminal growth (across)
A31: WACC \ terminal growth | B31: =$B$9-0.01 -> 0.02 | C31: =$B$9-0.005 -> 0.025 | D31: =$B$9 -> 0.03 | E31: =$B$9+0.005 -> 0.035 | F31: =$B$9+0.01 -> 0.04
A32: =$B$8-0.01 -> 0.0905 | B32: =(SUMPRODUCT($B$17:$K$17/(1+$A32)^$B$14:$K$14)+$K$17*(1+B$31)/($A32-B$31)/(1+$A32)^10-$B$26)/Assumptions!$C$6 -> 113.65333 | C32: =(SUMPRODUCT($B$17:$K$17/(1+$A32)^$B$14:$K$14)+$K$17*(1+C$31)/($A32-C$31)/(1+$A32)^10-$B$26)/Assumptions!$C$6 -> 119.43418 | D32: =(SUMPRODUCT($B$17:$K$17/(1+$A32)^$B$14:$K$14)+$K$17*(1+D$31)/($A32-D$31)/(1+$A32)^10-$B$26)/Assumptions!$C$6 -> 126.17055 | E32: =(SUMPRODUCT($B$17:$K$17/(1+$A32)^$B$14:$K$14)+$K$17*(1+E$31)/($A32-E$31)/(1+$A32)^10-$B$26)/Assumptions!$C$6 -> 134.12069 | F32: =(SUMPRODUCT($B$17:$K$17/(1+$A32)^$B$14:$K$14)+$K$17*(1+F$31)/($A32-F$31)/(1+$A32)^10-$B$26)/Assumptions!$C$6 -> 143.6451
A33: =$B$8-0.005 -> 0.0955 | B33: =(SUMPRODUCT($B$17:$K$17/(1+$A33)^$B$14:$K$14)+$K$17*(1+B$31)/($A33-B$31)/(1+$A33)^10-$B$26)/Assumptions!$C$6 -> 104.84686 | C33: =(SUMPRODUCT($B$17:$K$17/(1+$A33)^$B$14:$K$14)+$K$17*(1+C$31)/($A33-C$31)/(1+$A33)^10-$B$26)/Assumptions!$C$6 -> 109.65975 | D33: =(SUMPRODUCT($B$17:$K$17/(1+$A33)^$B$14:$K$14)+$K$17*(1+D$31)/($A33-D$31)/(1+$A33)^10-$B$26)/Assumptions!$C$6 -> 115.20744 | E33: =(SUMPRODUCT($B$17:$K$17/(1+$A33)^$B$14:$K$14)+$K$17*(1+E$31)/($A33-E$31)/(1+$A33)^10-$B$26)/Assumptions!$C$6 -> 121.6721 | F33: =(SUMPRODUCT($B$17:$K$17/(1+$A33)^$B$14:$K$14)+$K$17*(1+F$31)/($A33-F$31)/(1+$A33)^10-$B$26)/Assumptions!$C$6 -> 129.30156
A34: =$B$8 -> 0.1005 | B34: =(SUMPRODUCT($B$17:$K$17/(1+$A34)^$B$14:$K$14)+$K$17*(1+B$31)/($A34-B$31)/(1+$A34)^10-$B$26)/Assumptions!$C$6 -> 97.168587 | C34: =(SUMPRODUCT($B$17:$K$17/(1+$A34)^$B$14:$K$14)+$K$17*(1+C$31)/($A34-C$31)/(1+$A34)^10-$B$26)/Assumptions!$C$6 -> 101.21435 | D34: =(SUMPRODUCT($B$17:$K$17/(1+$A34)^$B$14:$K$14)+$K$17*(1+D$31)/($A34-D$31)/(1+$A34)^10-$B$26)/Assumptions!$C$6 -> 105.83398 | E34: =(SUMPRODUCT($B$17:$K$17/(1+$A34)^$B$14:$K$14)+$K$17*(1+E$31)/($A34-E$31)/(1+$A34)^10-$B$26)/Assumptions!$C$6 -> 111.1589 | F34: =(SUMPRODUCT($B$17:$K$17/(1+$A34)^$B$14:$K$14)+$K$17*(1+F$31)/($A34-F$31)/(1+$A34)^10-$B$26)/Assumptions!$C$6 -> 117.36396
A35: =$B$8+0.005 -> 0.1055 | B35: =(SUMPRODUCT($B$17:$K$17/(1+$A35)^$B$14:$K$14)+$K$17*(1+B$31)/($A35-B$31)/(1+$A35)^10-$B$26)/Assumptions!$C$6 -> 90.419336 | C35: =(SUMPRODUCT($B$17:$K$17/(1+$A35)^$B$14:$K$14)+$K$17*(1+C$31)/($A35-C$31)/(1+$A35)^10-$B$26)/Assumptions!$C$6 -> 93.84909 | D35: =(SUMPRODUCT($B$17:$K$17/(1+$A35)^$B$14:$K$14)+$K$17*(1+D$31)/($A35-D$31)/(1+$A35)^10-$B$26)/Assumptions!$C$6 -> 97.733115 | E35: =(SUMPRODUCT($B$17:$K$17/(1+$A35)^$B$14:$K$14)+$K$17*(1+E$31)/($A35-E$31)/(1+$A35)^10-$B$26)/Assumptions!$C$6 -> 102.16807 | F35: =(SUMPRODUCT($B$17:$K$17/(1+$A35)^$B$14:$K$14)+$K$17*(1+F$31)/($A35-F$31)/(1+$A35)^10-$B$26)/Assumptions!$C$6 -> 107.28011
A36: =$B$8+0.01 -> 0.1105 | B36: =(SUMPRODUCT($B$17:$K$17/(1+$A36)^$B$14:$K$14)+$K$17*(1+B$31)/($A36-B$31)/(1+$A36)^10-$B$26)/Assumptions!$C$6 -> 84.444008 | C36: =(SUMPRODUCT($B$17:$K$17/(1+$A36)^$B$14:$K$14)+$K$17*(1+C$31)/($A36-C$31)/(1+$A36)^10-$B$26)/Assumptions!$C$6 -> 87.373363 | D36: =(SUMPRODUCT($B$17:$K$17/(1+$A36)^$B$14:$K$14)+$K$17*(1+D$31)/($A36-D$31)/(1+$A36)^10-$B$26)/Assumptions!$C$6 -> 90.666612 | E36: =(SUMPRODUCT($B$17:$K$17/(1+$A36)^$B$14:$K$14)+$K$17*(1+E$31)/($A36-E$31)/(1+$A36)^10-$B$26)/Assumptions!$C$6 -> 94.396053 | F36: =(SUMPRODUCT($B$17:$K$17/(1+$A36)^$B$14:$K$14)+$K$17*(1+F$31)/($A36-F$31)/(1+$A36)^10-$B$26)/Assumptions!$C$6 -> 98.654493

Sheet Checks
A1: Integrity checks
A2: Illustrative: every figure is invented to show the format. Not investment advice. Subset shown. A full run adds balance sheet, quarters-sum-to-year, Q4-to-10-K and as-of date checks.
A3: Status | B3: =IF(COUNTIF(C6:C21,"FAIL")>0,"BLOCKED: "&COUNTIF(C6:C21,"FAIL")&" check(s) failed","No failures; "&COUNTIF(C6:C21,"FLAG")&" flag(s) for the reviewer") -> No failures; 1 flag(s) for the reviewer
A5: # | B5: Check | C5: Result | D5: Detail
A6: 1 | B6: Segment bookings sum to reported total (Q2 2026) | C6: =IF(ABS(Model!B16-Model!B6)<0.05,"PASS","FAIL") -> PASS | D6: =Model!B16-Model!B6 -> 0
A7: 2 | B7: Segment bookings sum to reported total (Q2 2025) | C7: =IF(ABS(Model!C16-Model!C6)<0.05,"PASS","FAIL") -> PASS | D7: =Model!C16-Model!C6 -> 0
A8: 3 | B8: Segment adj. EBITDA sums to reported total | C8: =IF(ABS(Model!B23-Model!B8)<0.005,"PASS","FAIL") -> PASS | D8: =Model!B23-Model!B8 -> 0
A9: 4 | B9: Take rate recomputes to the stated 26.8% | C9: =IF(ABS(Model!B9-0.268)<0.0005,"PASS","FAIL") -> PASS | D9: =Model!B9 -> 0.26819127
A10: 5 | B10: Revision bridge ties to Summary (all five estimates) | C10: =IF(SUMPRODUCT(--(ABS(Bridge!D21:D25)>0.005))=0,"PASS","FAIL") -> PASS | D10: =SUMPRODUCT(ABS(Bridge!D21:D25)) -> 3.7470027e-16
A11: 6 | B11: Scenario weights sum to 100% | C11: =IF(ROUND(Scenarios!C8,6)=1,"PASS","FAIL") -> PASS | D11: =Scenarios!C8 -> 1
A12: 7 | B12: Market cap ties to quoted figure | C12: =IF(ABS(Valuation!B7-Assumptions!$C$7)<0.5,"PASS","FAIL") -> PASS | D12: =Valuation!B7-Assumptions!$C$7 -> 0
A13: 8 | B13: Enterprise value ties to quoted figure | C13: =IF(ABS(Valuation!B9-Assumptions!$C$8)<0.5,"PASS","FAIL") -> PASS | D13: =Valuation!B9-Assumptions!$C$8 -> 0
A14: 9 | B14: Probability-weighted value within $0.50 of price target | C14: =IF(ABS(Scenarios!B8-Valuation!B35)<0.5,"PASS","FAIL") -> PASS | D14: =Scenarios!B8-Valuation!B35 -> 0
A15: 10 | B15: WACC exceeds terminal growth | C15: =IF(DCF!B8>DCF!B9,"PASS","FAIL") -> PASS | D15: =DCF!B8-DCF!B9 -> 0.0705
A16: 11 | B16: DCF grid centre equals DCF value | C16: =IF(ABS(DCF!D34-DCF!B28)<0.01,"PASS","FAIL") -> PASS | D16: =DCF!D34-DCF!B28 -> 0
A17: 12 | B17: Target multiple inside peer range | C17: =IF(Valuation!B28="inside range","PASS","FLAG") -> PASS | D17: =Valuation!B29 -> 0
A18: 13 | B18: Q3 bookings forecast within variance threshold of guidance midpoint | C18: =IF(ABS(Model!F37)<=Model!G37,"PASS","FLAG") -> PASS | D18: =Model!F37 -> 0.010731707
A19: 14 | B19: Q3 adj. EBITDA forecast within variance threshold of guidance midpoint | C19: =IF(ABS(Model!F38)<=Model!G38,"PASS","FLAG") -> PASS | D19: =Model!F38 -> 0.013333333
A20: 15 | B20: Q3 forecasts inside the guidance ranges | C20: =IF(AND(Model!E37>=Model!B37,Model!E37<=Model!C37,Model!E38>=Model!B38,Model!E38<=Model!C38),"PASS","FLAG") -> PASS | D20: =Model!E38-Model!D38 -> 0.03
A21: 16 | B21: Q2 adj. EBITDA: release vs. 10-Q segment note | C21: =IF(Model!B8=Model!B32,"PASS",IF(ABS(Model!B8-Model!B32)<=0.05,"FLAG","FAIL")) -> FLAG | D21: =Model!B8-Model!B32 -> 0.02

Sheet Log
A1: Evidence and exception log
A2: Illustrative: every figure is invented to show the format. Not investment advice. Filing and retrieval dates are invented.
A4: Evidence
A5: ID | B5: Figure or claim | C5: Value | D5: Source document | E5: Period | F5: Filing date | G5: Location | H5: Retrieved | I5: Type | J5: Workbook cell
A6: E-01 | B6: Q2 gross bookings ($B) | C6: 48.1 | D6: 8-K Ex. 99.1 | E6: Q2 2026 | F6: 2026-08-05 | G6: Financial highlights table | H6: 2026-08-06 | I6: reported | J6: Model!B6
A7: E-02 | B7: Q2 revenue ($B) | C7: 12.9 | D7: 8-K Ex. 99.1 | E7: Q2 2026 | F7: 2026-08-05 | G7: Financial highlights table | H7: 2026-08-06 | I7: reported | J7: Model!B7
A8: E-03 | B8: Q2 adj. EBITDA ($B) | C8: 2.1 | D8: 8-K Ex. 99.1 | E8: Q2 2026 | F8: 2026-08-05 | G8: Non-GAAP reconciliation | H8: 2026-08-06 | I8: reported | J8: Model!B8
A9: E-04 | B9: Q2 trips (B) | C9: 3.4 | D9: 8-K Ex. 99.1 | E9: Q2 2026 | F9: 2026-08-05 | G9: Financial highlights table | H9: 2026-08-06 | I9: reported | J9: Model!B5
A10: E-05 | B10: Q3 gross bookings guide ($B) | C10: 50.5-52.0 | D10: 8-K Ex. 99.1 | E10: Q3 2026 | F10: 2026-08-05 | G10: Outlook | H10: 2026-08-06 | I10: reported | J10: Model!B37:C37
A11: E-06 | B11: Q3 adj. EBITDA guide ($B) | C11: 2.2-2.3 | D11: 8-K Ex. 99.1 | E11: Q3 2026 | F11: 2026-08-05 | G11: Outlook | H11: 2026-08-06 | I11: reported | J11: Model!B38:C38
A12: E-07 | B12: Segment adj. EBITDA ($B) | C12: 1.50 / 0.80 / 0.02 / -0.22 | D12: 10-Q | E12: Q2 2026 | F12: 2026-08-05 | G12: Segment information note | H12: 2026-08-06 | I12: reported | J12: Model!B19:B22
A13: E-08 | B13: Adj. EBITDA per segment note ($B) | C13: 2.08 | D13: 10-Q | E13: Q2 2026 | F13: 2026-08-05 | G13: Segment information note | H13: 2026-08-06 | I13: reported | J13: Model!B32
A14: E-09 | B14: Share price ($) | C14: 80.00 | D14: Stooq daily close | E14: 2026-08-05 | F14: n/a | G14: Close | H14: 2026-08-06 | I14: reported | J14: Assumptions!C5
A15: E-10 | B15: Diluted shares (B) | C15: 2.0625 | D15: XBRL company facts | E15: Q2 2026 | F15: 2026-08-05 | G15: WeightedAverageNumberOfDilutedSharesOutstanding | H15: 2026-08-06 | I15: reported | J15: Assumptions!C6
A16: E-11 | B16: Take rate | C16: 26.8% | D16: Derived: revenue / gross bookings | E16: Q2 2026 | F16: n/a | G16: n/a | H16: 2026-08-06 | I16: derived | J16: Model!B9
... A19: E-14 | B19: Equity risk premium | C19: 4.5% | D19: Damodaran implied ERP | E19: Latest before 2026-08-06 | F19: n/a | G19: Implied ERP file | H19: 2026-08-06 | I19: reported | J19: DCF!B6
A21: Exceptions
A22: ID | B22: Severity | C22: Item | D22: Treatment | E22: Status | F22: Where it appears
A23: X-01 | B23: Warning | C23: Q2 adj. EBITDA 2.1 (release) vs. 2.08 (10-Q) | D23: Rounding; the filing wins (collection rules) | E23: Open | F23: Note 4.3; Checks #16
A24: X-02 | B24: Data gap | C24: AV economics not disclosed | D24: Scenario only, not a forecast | E24: Open | F24: Note 3.3, 7
A25: X-03 | B25: Information | C25: No consensus source | D25: Benchmark against guidance and baselines | E25: Open | F25: Note 2.1
A26: X-04 | B26: Information | C26: Three peers only | D26: Flag the thin range | E26: Open | F26: Note 6
A27: X-05 | B27: Information | C27: Next earnings date not announced | D27: Mark as estimated | E27: Open | F27: Note 1, 8
